export const catchAsyncErrors = (theFunction) => {
  return (req, res, next) => {
    Promise.resolve(theFunction(req, res, next)).catch(next);
  };
};
//calling catch with next triggers error handling mechanism in express 
